<?xml version="1.0" ?>
<!-- =================================================================================== -->
<!-- |    This document was autogenerated by xacro from rover_model.urdf.xacro         | -->
<!-- |    EDITING THIS FILE BY HAND IS NOT RECOMMENDED                                 | -->
<!-- =================================================================================== -->
<robot name="rover" xmlns:xacro="http://www.ros.org/wiki/xacro">
  <!--Base Link-->
  <link name="base_link">
    <visual>
      <geometry>
        <box size=".63 1.29 .505"/>
      </geometry>
      <origin rpy="0 0 0" xyz="0 0 0"/>
      <material name="orange">
        <color rgba="0.913 0.443 0.086 1"/>
      </material>
    </visual>
    <collision>
      <geometry>
        <box size=".63 1.29 .505"/>
      </geometry>
      <origin rpy="0 0 0" xyz="0 0 0"/>
    </collision>
    <inertial>
      <mass value="1.0"/>
      <inertia ixx="0.015" ixy="0" ixz="0" iyy="0.0375" iyz="0" izz="0.0375"/>
    </inertial>
  </link>
  <link name="R1_wheel">
    <visual>
      <geometry>
        <cylinder length="0.13" radius="0.125"/>
      </geometry>
      <origin rpy="0 1.55 0" xyz="0.5 0 0"/>
      <material name="black">
        <color rgba="0 0 0 1"/>
      </material>
    </visual>
    <collision>
      <geometry>
        <cylinder length="0.13" radius="0.125"/>
      </geometry>
      <origin rpy="0 1.55 0" xyz="0.5 0 0"/>
    </collision>
    <inertial>
      <mass value="0.1"/>
      <inertia ixx="5.1458e-5" ixy="0" ixz="0" iyy="5.1458e-5" iyz="0" izz="6.125e-5"/>
    </inertial>
  </link>
  <joint name="base_to_R1_wheel" type="continuous">
    <parent link="base_link"/>
    <child link="R1_wheel"/>
    <origin xyz="0 0.52 -0.25"/>
    <axis xyz="1 0 0"/>
  </joint>
  <link name="R2_wheel">
    <visual>
      <geometry>
        <cylinder length="0.13" radius="0.125"/>
      </geometry>
      <origin rpy="0 1.55 0" xyz="0.5 0 0"/>
      <material name="black">
        <color rgba="0 0 0 1"/>
      </material>
    </visual>
    <collision>
      <geometry>
        <cylinder length="0.13" radius="0.125"/>
      </geometry>
      <origin rpy="0 1.55 0" xyz="0.5 0 0"/>
    </collision>
    <inertial>
      <mass value="0.1"/>
      <inertia ixx="5.1458e-5" ixy="0" ixz="0" iyy="5.1458e-5" iyz="0" izz="6.125e-5"/>
    </inertial>
  </link>
  <joint name="base_to_R2_wheel" type="continuous">
    <parent link="base_link"/>
    <child link="R2_wheel"/>
    <origin xyz="0 0 -0.25"/>
    <axis xyz="1 0 0"/>
  </joint>
  <link name="R3_wheel">
    <visual>
      <geometry>
        <cylinder length="0.13" radius="0.125"/>
      </geometry>
      <origin rpy="0 1.55 0" xyz="0.5 0 0"/>
      <material name="black">
        <color rgba="0 0 0 1"/>
      </material>
    </visual>
    <collision>
      <geometry>
        <cylinder length="0.13" radius="0.125"/>
      </geometry>
      <origin rpy="0 1.55 0" xyz="0.5 0 0"/>
    </collision>
    <inertial>
      <mass value="0.1"/>
      <inertia ixx="5.1458e-5" ixy="0" ixz="0" iyy="5.1458e-5" iyz="0" izz="6.125e-5"/>
    </inertial>
  </link>
  <joint name="base_to_R3_wheel" type="continuous">
    <parent link="base_link"/>
    <child link="R3_wheel"/>
    <origin xyz="0 -0.52 -0.25"/>
    <axis xyz="1 0 0"/>
  </joint>
  <link name="L1_wheel">
    <visual>
      <geometry>
        <cylinder length="0.13" radius="0.125"/>
      </geometry>
      <origin rpy="0 1.55 0" xyz="-0.5 0 0"/>
      <material name="black">
        <color rgba="0 0 0 1"/>
      </material>
    </visual>
    <collision>
      <geometry>
        <cylinder length="0.13" radius="0.125"/>
      </geometry>
      <origin rpy="0 1.55 0" xyz="-0.5 0 0"/>
    </collision>
    <inertial>
      <mass value="0.1"/>
      <inertia ixx="5.1458e-5" ixy="0" ixz="0" iyy="5.1458e-5" iyz="0" izz="6.125e-5"/>
    </inertial>
  </link>
  <joint name="base_to_L1_wheel" type="continuous">
    <parent link="base_link"/>
    <child link="L1_wheel"/>
    <origin xyz="0 0.52 -0.25"/>
    <axis xyz="1 0 0"/>
  </joint>
  <link name="L2_wheel">
    <visual>
      <geometry>
        <cylinder length="0.13" radius="0.125"/>
      </geometry>
      <origin rpy="0 1.55 0" xyz="-0.5 0 0"/>
      <material name="black">
        <color rgba="0 0 0 1"/>
      </material>
    </visual>
    <collision>
      <geometry>
        <cylinder length="0.13" radius="0.125"/>
      </geometry>
      <origin rpy="0 1.55 0" xyz="-0.5 0 0"/>
    </collision>
    <inertial>
      <mass value="0.1"/>
      <inertia ixx="5.1458e-5" ixy="0" ixz="0" iyy="5.1458e-5" iyz="0" izz="6.125e-5"/>
    </inertial>
  </link>
  <joint name="base_to_L2_wheel" type="continuous">
    <parent link="base_link"/>
    <child link="L2_wheel"/>
    <origin xyz="0 0 -0.25"/>
    <axis xyz="1 0 0"/>
  </joint>
  <link name="L3_wheel">
    <visual>
      <geometry>
        <cylinder length="0.13" radius="0.125"/>
      </geometry>
      <origin rpy="0 1.55 0" xyz="-0.5 0 0"/>
      <material name="black">
        <color rgba="0 0 0 1"/>
      </material>
    </visual>
    <collision>
      <geometry>
        <cylinder length="0.13" radius="0.125"/>
      </geometry>
      <origin rpy="0 1.55 0" xyz="-0.5 0 0"/>
    </collision>
    <inertial>
      <mass value="0.1"/>
      <inertia ixx="5.1458e-5" ixy="0" ixz="0" iyy="5.1458e-5" iyz="0" izz="6.125e-5"/>
    </inertial>
  </link>
  <joint name="base_to_L3_wheel" type="continuous">
    <parent link="base_link"/>
    <child link="L3_wheel"/>
    <origin xyz="0 -0.52 -0.25"/>
    <axis xyz="1 0 0"/>
  </joint>
  <!--Lidar Supprt Rod-->
  <link name="lidar_support_rod">
    <visual>
      <geometry>
        <cylinder length="0.34" radius="0.035"/>
      </geometry>
      <origin xyz="0 0.61 0.4225"/>
      <material name="black">
        <color rgba="0 0 0 1"/>
      </material>
    </visual>
    <collision>
      <geometry>
        <cylinder length="0.34" radius="0.035"/>
      </geometry>
      <origin xyz="0 0.61 0.4225"/>
    </collision>
    <inertial>
      <mass value="1.0"/>
      <inertia ixx="0.015" ixy="0" ixz="0" iyy="0.0375" iyz="0" izz="0.0375"/>
    </inertial>
  </link>
  <joint name="base_to_lidar_support_rod" type="fixed">
    <parent link="base_link"/>
    <child link="lidar_support_rod"/>
  </joint>
</robot>
